<?xml version="1.0" ?>
<!-- =================================================================================== -->
<!-- |    This document was autogenerated by xacro from /home/greg/wifibot_ws/src/pincher_arm/pincher_arm_description/urdf/pincher_arm.urdf.xacro | -->
<!-- |    EDITING THIS FILE BY HAND IS NOT RECOMMENDED                                 | -->
<!-- =================================================================================== -->
<robot name="pincher_arm">
    <!-- 300 degrees -->
    <material name="White">
        <color rgba="0.87 0.90 0.87 1.0" />
    </material>
    <material name="Black">
        <color rgba="0.08 0.08 0.08 1.0" />
    </material>
    <material name="Gray">
        <color rgba="0.2 0.2 0.21 1.0" />
    </material>
    <material name="Green">
        <color rgba="0.22 0.32 0.14 1.0" />
    </material>
    <link name="arm_base_link" />
    <joint name="arm_shoulder_pan_servo_joint" type="fixed">
        <origin rpy="1.5707963267948966 0 1.5707963267948966" xyz="0 0 0" />
        <parent link="arm_base_link" />
        <child link="arm_shoulder_pan_servo_link" />
    </joint>
    <link name="arm_shoulder_pan_servo_link">
        <inertial>
            <mass value="0.055" />
            <origin xyz="0 0 -0.01241" rpy="0 0 0" />
            <inertia ixx="1.807666666666667e-05" ixy="0" ixz="0" iyy="1.8251979166666668e-05" iyz="0" izz="1.3411979166666667e-05" />
        </inertial>
        <visual>
            <origin rpy="0 0 0" xyz="0 0 0" />
            <geometry>
                <mesh filename="package://pincher_arm_description/meshes/ax12_box.stl" scale="0.001 0.001 0.001" />
            </geometry>
            <material name="Black" />
        </visual>
        <collision>
            <origin rpy="0 0 0" xyz="0.0 0.0 -0.01241" />
            <geometry>
                <box size="0.0385 0.038 0.05" />
            </geometry>
        </collision>
    </link>
    <gazebo reference="arm_shoulder_pan_servo_link">
        <material>Gazebo/Black</material>
        <selfCollide>true</selfCollide>
        <gravity>true</gravity>
        <plugin name="gazebo_ros_control">
            <robotNamespace>/</robotNamespace>
        </plugin>
    </gazebo>
    <joint name="arm_shoulder_pan_joint" type="revolute">
        <origin rpy="-1.5707963267948966 1.5707963267948966 3.141592653589793" xyz="0 0.019 0" />
        <axis xyz="0 0 -1" />
        <limit effort="30" lower="-2.617" upper="2.617" velocity="1.571" />
        <dynamics friction="0.13" />
        <parent link="arm_shoulder_pan_servo_link" />
        <child link="arm_shoulder_pan_link" />
    </joint>
    <link name="arm_shoulder_pan_link">
        <inertial>
            <mass value="0.008" />
            <origin xyz="0 0 0" rpy="0 0 0" />
            <inertia ixx="1.0166666666666665e-06" ixy="0" ixz="0" iyy="4.7066666666666675e-07" iyz="0" izz="1.3793333333333333e-06" />
        </inertial>
        <visual>
            <origin rpy="0 0 0" xyz="0 0 0" />
            <geometry>
                <mesh filename="package://pincher_arm_description/meshes/F3.stl" scale="0.001 0.001 0.001" />
            </geometry>
            <material name="Gray" />
        </visual>
        <collision>
            <origin rpy="0 0 0" xyz="0.0 0.0 -0.0045" />
            <geometry>
                <box size="0.025 0.038 0.009" />
            </geometry>
        </collision>
    </link>
    <gazebo reference="arm_shoulder_pan_link">
        <material>Gazebo/Gray</material>
        <selfCollide>true</selfCollide>
        <gravity>true</gravity>
    </gazebo>
    <joint name="arm_shoulder_lift_servo_joint" type="fixed">
        <origin rpy="0 3.141592653589793 0" xyz="0 0 -0.041499999999999995" />
        <parent link="arm_shoulder_pan_link" />
        <child link="arm_shoulder_lift_servo_link" />
    </joint>
    <link name="arm_shoulder_lift_servo_link">
        <inertial>
            <mass value="0.055" />
            <origin xyz="0 0 -0.01241" rpy="0 0 0" />
            <inertia ixx="1.807666666666667e-05" ixy="0" ixz="0" iyy="1.8251979166666668e-05" iyz="0" izz="1.3411979166666667e-05" />
        </inertial>
        <visual>
            <origin rpy="0 0 0" xyz="0 0 0" />
            <geometry>
                <mesh filename="package://pincher_arm_description/meshes/ax12_box.stl" scale="0.001 0.001 0.001" />
            </geometry>
            <material name="Black" />
        </visual>
        <collision>
            <origin rpy="0 0 0" xyz="0.0 0.0 -0.01241" />
            <geometry>
                <box size="0.0385 0.038 0.05" />
            </geometry>
        </collision>
    </link>
    <gazebo reference="arm_shoulder_lift_servo_link">
        <material>Gazebo/Black</material>
        <selfCollide>true</selfCollide>
        <gravity>true</gravity>
    </gazebo>
    <joint name="arm_shoulder_lift_joint" type="revolute">
        <origin rpy="0 0 0" xyz="0 0 0" />
        <axis xyz="0 1 0" />
        <limit effort="30" lower="-2.09" upper="2.09" velocity="1.571" />
        <dynamics friction="0.13" />
        <parent link="arm_shoulder_lift_servo_link" />
        <child link="arm_shoulder_lift_link" />
    </joint>
    <link name="arm_shoulder_lift_link">
        <inertial>
            <mass value="0.016" />
            <origin xyz="0 0 0" rpy="0 0 0" />
            <inertia ixx="8.769666666666667e-06" ixy="0" ixz="0" iyy="6.678666666666667e-06" iyz="0" izz="4.181666666666667e-06" />
        </inertial>
        <visual>
            <origin rpy="0 0 0" xyz="0 0 0" />
            <geometry>
                <mesh filename="package://pincher_arm_description/meshes/F4.stl" scale="0.001 0.001 0.001" />
            </geometry>
            <material name="Gray" />
        </visual>
        <collision>
            <origin rpy="0 0 0" xyz="0.0 0.0 0.0215" />
            <geometry>
                <box size="0.028 0.0485 0.065" />
            </geometry>
        </collision>
    </link>
    <gazebo reference="arm_shoulder_lift_link">
        <material>Gazebo/Gray</material>
        <selfCollide>true</selfCollide>
        <gravity>true</gravity>
    </gazebo>
    <joint name="arm_shoulder_F10_0_joint" type="fixed">
        <origin rpy="0 0 0" xyz="0 0 0.0545" />
        <parent link="arm_shoulder_lift_link" />
        <child link="arm_shoulder_F10_0_link" />
    </joint>
    <link name="arm_shoulder_F10_0_link">
        <inertial>
            <mass value="0.004" />
            <origin xyz="0 0 0" rpy="0 0 0" />
            <inertia ixx="4.866666666666666e-07" ixy="0" ixz="0" iyy="2.136666666666667e-07" iyz="0" izz="6.896666666666666e-07" />
        </inertial>
        <visual>
            <origin rpy="0 0 0" xyz="0 0 0" />
            <geometry>
                <mesh filename="package://pincher_arm_description/meshes/F10.stl" scale="0.001 0.001 0.001" />
            </geometry>
            <material name="Gray" />
        </visual>
        <collision>
            <origin rpy="0 0 0" xyz="0.0 0.0 0.0" />
            <geometry>
                <box size="0.025 0.038 0.004" />
            </geometry>
        </collision>
    </link>
    <gazebo reference="arm_shoulder_F10_0_link">
        <material>Gazebo/Gray</material>
        <selfCollide>true</selfCollide>
        <gravity>true</gravity>
    </gazebo>
    <joint name="arm_shoulder_F10_1_joint" type="fixed">
        <origin rpy="0 0 0" xyz="0 0 0.004" />
        <parent link="arm_shoulder_F10_0_link" />
        <child link="arm_shoulder_F10_1_link" />
    </joint>
    <link name="arm_shoulder_F10_1_link">
        <inertial>
            <mass value="0.004" />
            <origin xyz="0 0 0" rpy="0 0 0" />
            <inertia ixx="4.866666666666666e-07" ixy="0" ixz="0" iyy="2.136666666666667e-07" iyz="0" izz="6.896666666666666e-07" />
        </inertial>
        <visual>
            <origin rpy="0 0 0" xyz="0 0 0" />
            <geometry>
                <mesh filename="package://pincher_arm_description/meshes/F10.stl" scale="0.001 0.001 0.001" />
            </geometry>
            <material name="Gray" />
        </visual>
        <collision>
            <origin rpy="0 0 0" xyz="0.0 0.0 0.0" />
            <geometry>
                <box size="0.025 0.038 0.004" />
            </geometry>
        </collision>
    </link>
    <gazebo reference="arm_shoulder_F10_1_link">
        <material>Gazebo/Gray</material>
        <selfCollide>true</selfCollide>
        <gravity>true</gravity>
    </gazebo>
    <joint name="arm_shoulder_F10_2_joint" type="fixed">
        <origin rpy="0 0 0" xyz="0 0 0.004" />
        <parent link="arm_shoulder_F10_1_link" />
        <child link="arm_shoulder_F10_2_link" />
    </joint>
    <link name="arm_shoulder_F10_2_link">
        <inertial>
            <mass value="0.004" />
            <origin xyz="0 0 0" rpy="0 0 0" />
            <inertia ixx="4.866666666666666e-07" ixy="0" ixz="0" iyy="2.136666666666667e-07" iyz="0" izz="6.896666666666666e-07" />
        </inertial>
        <visual>
            <origin rpy="0 0 0" xyz="0 0 0" />
            <geometry>
                <mesh filename="package://pincher_arm_description/meshes/F10.stl" scale="0.001 0.001 0.001" />
            </geometry>
            <material name="Gray" />
        </visual>
        <collision>
            <origin rpy="0 0 0" xyz="0.0 0.0 0.0" />
            <geometry>
                <box size="0.025 0.038 0.004" />
            </geometry>
        </collision>
    </link>
    <gazebo reference="arm_shoulder_F10_2_link">
        <material>Gazebo/Gray</material>
        <selfCollide>true</selfCollide>
        <gravity>true</gravity>
    </gazebo>
    <joint name="arm_shoulder_F3_0_joint" type="fixed">
        <origin rpy="0 3.141592653589793 0" xyz="0 0 0.002" />
        <parent link="arm_shoulder_F10_2_link" />
        <child link="arm_shoulder_F3_0_link" />
    </joint>
    <link name="arm_shoulder_F3_0_link">
        <inertial>
            <mass value="0.005" />
            <origin xyz="0 0 0" rpy="0 0 0" />
            <inertia ixx="6.354166666666667e-07" ixy="0" ixz="0" iyy="2.9416666666666673e-07" iyz="0" izz="8.620833333333335e-07" />
        </inertial>
        <visual>
            <origin rpy="0 0 0" xyz="0 0 0" />
            <geometry>
                <mesh filename="package://pincher_arm_description/meshes/F3.stl" scale="0.001 0.001 0.001" />
            </geometry>
            <material name="Gray" />
        </visual>
        <collision>
            <origin rpy="0 0 0" xyz="0.0 0.0 -0.0045" />
            <geometry>
                <box size="0.025 0.038 0.009" />
            </geometry>
        </collision>
    </link>
    <gazebo reference="arm_shoulder_F3_0_link">
        <material>Gazebo/Gray</material>
        <selfCollide>true</selfCollide>
        <gravity>true</gravity>
    </gazebo>
    <joint name="arm_elbow_flex_servo_joint" type="fixed">
        <origin rpy="0 3.141592653589793 0" xyz="0 0 -0.041499999999999995" />
        <parent link="arm_shoulder_F3_0_link" />
        <child link="arm_elbow_flex_servo_link" />
    </joint>
    <link name="arm_elbow_flex_servo_link">
        <inertial>
            <mass value="0.055" />
            <origin xyz="0 0 -0.01241" rpy="0 0 0" />
            <inertia ixx="1.807666666666667e-05" ixy="0" ixz="0" iyy="1.8251979166666668e-05" iyz="0" izz="1.3411979166666667e-05" />
        </inertial>
        <visual>
            <origin rpy="0 0 0" xyz="0 0 0" />
            <geometry>
                <mesh filename="package://pincher_arm_description/meshes/ax12_box.stl" scale="0.001 0.001 0.001" />
            </geometry>
            <material name="Black" />
        </visual>
        <collision>
            <origin rpy="0 0 0" xyz="0.0 0.0 -0.01241" />
            <geometry>
                <box size="0.0385 0.038 0.05" />
            </geometry>
        </collision>
    </link>
    <gazebo reference="arm_elbow_flex_servo_link">
        <material>Gazebo/Black</material>
        <selfCollide>true</selfCollide>
        <gravity>true</gravity>
    </gazebo>
    <joint name="arm_elbow_flex_joint" type="revolute">
        <origin rpy="0 0 0" xyz="0 0 0" />
        <axis xyz="0 1 0" />
        <limit effort="30" lower="-2.42" upper="2.42" velocity="1.571" />
        <dynamics friction="0.13" />
        <parent link="arm_elbow_flex_servo_link" />
        <child link="arm_elbow_flex_link" />
    </joint>
    <link name="arm_elbow_flex_link">
        <inertial>
            <mass value="0.016" />
            <origin xyz="0 0 0" rpy="0 0 0" />
            <inertia ixx="8.769666666666667e-06" ixy="0" ixz="0" iyy="6.678666666666667e-06" iyz="0" izz="4.181666666666667e-06" />
        </inertial>
        <visual>
            <origin rpy="0 0 0" xyz="0 0 0" />
            <geometry>
                <mesh filename="package://pincher_arm_description/meshes/F4.stl" scale="0.001 0.001 0.001" />
            </geometry>
            <material name="Gray" />
        </visual>
        <collision>
            <origin rpy="0 0 0" xyz="0.0 0.0 0.0215" />
            <geometry>
                <box size="0.028 0.0485 0.065" />
            </geometry>
        </collision>
    </link>
    <gazebo reference="arm_elbow_flex_link">
        <material>Gazebo/Gray</material>
        <selfCollide>true</selfCollide>
        <gravity>true</gravity>
    </gazebo>
    <joint name="arm_elbow_F10_0_joint" type="fixed">
        <origin rpy="0 0 0" xyz="0 0 0.0545" />
        <parent link="arm_elbow_flex_link" />
        <child link="arm_elbow_F10_0_link" />
    </joint>
    <link name="arm_elbow_F10_0_link">
        <inertial>
            <mass value="0.004" />
            <origin xyz="0 0 0" rpy="0 0 0" />
            <inertia ixx="4.866666666666666e-07" ixy="0" ixz="0" iyy="2.136666666666667e-07" iyz="0" izz="6.896666666666666e-07" />
        </inertial>
        <visual>
            <origin rpy="0 0 0" xyz="0 0 0" />
            <geometry>
                <mesh filename="package://pincher_arm_description/meshes/F10.stl" scale="0.001 0.001 0.001" />
            </geometry>
            <material name="Gray" />
        </visual>
        <collision>
            <origin rpy="0 0 0" xyz="0.0 0.0 0.0" />
            <geometry>
                <box size="0.025 0.038 0.004" />
            </geometry>
        </collision>
    </link>
    <gazebo reference="arm_elbow_F10_0_link">
        <material>Gazebo/Gray</material>
        <selfCollide>true</selfCollide>
        <gravity>true</gravity>
    </gazebo>
    <joint name="arm_elbow_F10_1_joint" type="fixed">
        <origin rpy="0 0 0" xyz="0 0 0.004" />
        <parent link="arm_elbow_F10_0_link" />
        <child link="arm_elbow_F10_1_link" />
    </joint>
    <link name="arm_elbow_F10_1_link">
        <inertial>
            <mass value="0.004" />
            <origin xyz="0 0 0" rpy="0 0 0" />
            <inertia ixx="4.866666666666666e-07" ixy="0" ixz="0" iyy="2.136666666666667e-07" iyz="0" izz="6.896666666666666e-07" />
        </inertial>
        <visual>
            <origin rpy="0 0 0" xyz="0 0 0" />
            <geometry>
                <mesh filename="package://pincher_arm_description/meshes/F10.stl" scale="0.001 0.001 0.001" />
            </geometry>
            <material name="Gray" />
        </visual>
        <collision>
            <origin rpy="0 0 0" xyz="0.0 0.0 0.0" />
            <geometry>
                <box size="0.025 0.038 0.004" />
            </geometry>
        </collision>
    </link>
    <gazebo reference="arm_elbow_F10_1_link">
        <material>Gazebo/Gray</material>
        <selfCollide>true</selfCollide>
        <gravity>true</gravity>
    </gazebo>
    <joint name="arm_elbow_F10_2_joint" type="fixed">
        <origin rpy="0 0 0" xyz="0 0 0.004" />
        <parent link="arm_elbow_F10_1_link" />
        <child link="arm_elbow_F10_2_link" />
    </joint>
    <link name="arm_elbow_F10_2_link">
        <inertial>
            <mass value="0.004" />
            <origin xyz="0 0 0" rpy="0 0 0" />
            <inertia ixx="4.866666666666666e-07" ixy="0" ixz="0" iyy="2.136666666666667e-07" iyz="0" izz="6.896666666666666e-07" />
        </inertial>
        <visual>
            <origin rpy="0 0 0" xyz="0 0 0" />
            <geometry>
                <mesh filename="package://pincher_arm_description/meshes/F10.stl" scale="0.001 0.001 0.001" />
            </geometry>
            <material name="Gray" />
        </visual>
        <collision>
            <origin rpy="0 0 0" xyz="0.0 0.0 0.0" />
            <geometry>
                <box size="0.025 0.038 0.004" />
            </geometry>
        </collision>
    </link>
    <gazebo reference="arm_elbow_F10_2_link">
        <material>Gazebo/Gray</material>
        <selfCollide>true</selfCollide>
        <gravity>true</gravity>
    </gazebo>
    <joint name="arm_elbow_F3_0_joint" type="fixed">
        <origin rpy="0 3.141592653589793 0" xyz="0 0 0.002" />
        <parent link="arm_elbow_F10_2_link" />
        <child link="arm_elbow_F3_0_link" />
    </joint>
    <link name="arm_elbow_F3_0_link">
        <inertial>
            <mass value="0.005" />
            <origin xyz="0 0 0" rpy="0 0 0" />
            <inertia ixx="6.354166666666667e-07" ixy="0" ixz="0" iyy="2.9416666666666673e-07" iyz="0" izz="8.620833333333335e-07" />
        </inertial>
        <visual>
            <origin rpy="0 0 0" xyz="0 0 0" />
            <geometry>
                <mesh filename="package://pincher_arm_description/meshes/F3.stl" scale="0.001 0.001 0.001" />
            </geometry>
            <material name="Gray" />
        </visual>
        <collision>
            <origin rpy="0 0 0" xyz="0.0 0.0 -0.0045" />
            <geometry>
                <box size="0.025 0.038 0.009" />
            </geometry>
        </collision>
    </link>
    <gazebo reference="arm_elbow_F3_0_link">
        <material>Gazebo/Gray</material>
        <selfCollide>true</selfCollide>
        <gravity>true</gravity>
    </gazebo>
    <joint name="arm_wrist_flex_servo_joint" type="fixed">
        <origin rpy="0 3.141592653589793 0" xyz="0 0 -0.041499999999999995" />
        <parent link="arm_elbow_F3_0_link" />
        <child link="arm_wrist_flex_servo_link" />
    </joint>
    <link name="arm_wrist_flex_servo_link">
        <inertial>
            <mass value="0.055" />
            <origin xyz="0 0 -0.01241" rpy="0 0 0" />
            <inertia ixx="1.807666666666667e-05" ixy="0" ixz="0" iyy="1.8251979166666668e-05" iyz="0" izz="1.3411979166666667e-05" />
        </inertial>
        <visual>
            <origin rpy="0 0 0" xyz="0 0 0" />
            <geometry>
                <mesh filename="package://pincher_arm_description/meshes/ax12_box.stl" scale="0.001 0.001 0.001" />
            </geometry>
            <material name="Black" />
        </visual>
        <collision>
            <origin rpy="0 0 0" xyz="0.0 0.0 -0.01241" />
            <geometry>
                <box size="0.0385 0.038 0.05" />
            </geometry>
        </collision>
    </link>
    <gazebo reference="arm_wrist_flex_servo_link">
        <material>Gazebo/Black</material>
        <selfCollide>true</selfCollide>
        <gravity>true</gravity>
    </gazebo>
    <joint name="arm_wrist_flex_joint" type="revolute">
        <origin rpy="0 0 0" xyz="0 0 0" />
        <axis xyz="0 1 0" />
        <limit effort="30" lower="-1.71" upper="1.79" velocity="1.571" />
        <dynamics friction="0.13" />
        <parent link="arm_wrist_flex_servo_link" />
        <child link="arm_wrist_flex_link" />
    </joint>
    <link name="arm_wrist_flex_link">
        <inertial>
            <mass value="0.01" />
            <origin xyz="0 0 0" rpy="0 0 0" />
            <inertia ixx="3.1320833333333338e-06" ixy="0" ixz="0" iyy="1.6927083333333335e-06" iyz="0" izz="2.4810416666666672e-06" />
        </inertial>
        <visual>
            <origin rpy="0 0 0" xyz="0 0 0" />
            <geometry>
                <mesh filename="package://pincher_arm_description/meshes/F2.stl" scale="0.001 0.001 0.001" />
            </geometry>
            <material name="Gray" />
        </visual>
        <collision>
            <origin rpy="0 0 0" xyz="0.0 0.0 0.00775" />
            <geometry>
                <box size="0.025 0.0485 0.0375" />
            </geometry>
        </collision>
    </link>
    <gazebo reference="arm_wrist_flex_link">
        <material>Gazebo/Gray</material>
        <selfCollide>true</selfCollide>
        <gravity>true</gravity>
    </gazebo>
    <joint name="arm_wrist_F3_0_joint" type="fixed">
        <origin rpy="0 3.141592653589793 -3.141592653589793" xyz="0 0 0.0265" />
        <parent link="arm_wrist_flex_link" />
        <child link="arm_wrist_F3_0_link" />
    </joint>
    <link name="arm_wrist_F3_0_link">
        <inertial>
            <mass value="0.005" />
            <origin xyz="0 0 0" rpy="0 0 0" />
            <inertia ixx="6.354166666666667e-07" ixy="0" ixz="0" iyy="2.9416666666666673e-07" iyz="0" izz="8.620833333333335e-07" />
        </inertial>
        <visual>
            <origin rpy="0 0 0" xyz="0 0 0" />
            <geometry>
                <mesh filename="package://pincher_arm_description/meshes/F3.stl" scale="0.001 0.001 0.001" />
            </geometry>
            <material name="Gray" />
        </visual>
        <collision>
            <origin rpy="0 0 0" xyz="0.0 0.0 -0.0045" />
            <geometry>
                <box size="0.025 0.038 0.009" />
            </geometry>
        </collision>
    </link>
    <gazebo reference="arm_wrist_F3_0_link">
        <material>Gazebo/Gray</material>
        <selfCollide>true</selfCollide>
        <gravity>true</gravity>
    </gazebo>
    <joint name="gripper_servo_joint" type="fixed">
        <origin rpy="1.5707963267948966 3.141592653589793 1.5707963267948966" xyz="0 0 -0.019" />
        <parent link="arm_wrist_F3_0_link" />
        <child link="gripper_servo_link" />
    </joint>
    <link name="gripper_servo_link">
        <inertial>
            <mass value="0.055" />
            <origin xyz="0 0 -0.01241" rpy="0 0 0" />
            <inertia ixx="1.807666666666667e-05" ixy="0" ixz="0" iyy="1.8251979166666668e-05" iyz="0" izz="1.3411979166666667e-05" />
        </inertial>
        <visual>
            <origin rpy="0 0 0" xyz="0 0 0" />
            <geometry>
                <mesh filename="package://pincher_arm_description/meshes/ax12_box.stl" scale="0.001 0.001 0.001" />
            </geometry>
            <material name="Black" />
        </visual>
        <collision>
            <origin rpy="0 0 0" xyz="0.0 0.0 -0.01241" />
            <geometry>
                <box size="0.0385 0.038 0.05" />
            </geometry>
        </collision>
    </link>
    <gazebo reference="gripper_servo_link">
        <material>Gazebo/Black</material>
        <selfCollide>true</selfCollide>
        <gravity>true</gravity>
    </gazebo>
    <joint name="gripper_finger_base_joint" type="fixed">
        <origin rpy="3.141592653589793 0 1.5707963267948966" xyz="0  0.019 0" />
        <parent link="gripper_servo_link" />
        <child link="gripper_finger_base_link" />
    </joint>
    <link name="gripper_finger_base_link">
        <inertial>
            <mass value="1e-05" />
            <origin xyz="0 0 0" rpy="0 0 0" />
            <inertia ixx="6.0208333333333335e-09" ixy="0" ixz="0" iyy="1.336666666666667e-09" iyz="0" izz="4.690833333333333e-09" />
        </inertial>
        <visual>
            <origin rpy="0 0 0" xyz="0 0 0" />
            <geometry>
                <box size="0.002 0.075 0.040" />
            </geometry>
            <material name="Gray" />
        </visual>
        <collision>
            <geometry>
                <box size="0.002 0.075 0.040" />
            </geometry>
        </collision>
    </link>
    <gazebo reference="gripper_finger_base_link">
        <material>Gazebo/Gray</material>
        <selfCollide>true</selfCollide>
        <gravity>true</gravity>
    </gazebo>
    <link name="gripper_active_link" />
    <joint name="gripper_joint" type="revolute">
        <origin rpy="0 0 0" xyz="0 0 0" />
        <axis xyz="1 0 0" />
        <limit effort="30" lower="-2.6" upper="0.0" velocity="1.571" />
        <parent link="gripper_finger_base_link" />
        <child link="gripper_active_link" />
    </joint>
    <link name="gripper_finger1_link">
        <inertial>
            <mass value="1e-05" />
            <origin xyz="0 0 0" rpy="0 0 0" />
            <inertia ixx="6.666666666666667e-10" ixy="0" ixz="0" iyy="1.0933333333333333e-09" iyz="0" izz="1.7333333333333333e-09" />
        </inertial>
        <visual>
            <origin rpy="1.5707963267948966 0 1.5707963267948966" xyz="0 0.0115 0" />
            <geometry>
                <mesh filename="package://pincher_arm_description/meshes/pincher_finger.stl" scale=".01 .01 .01" />
            </geometry>
            <material name="Gray" />
        </visual>
        <collision>
            <origin rpy="1.5707963267948966 0 1.5707963267948966" xyz="0 0.0115 0" />
            <geometry>
                <box size="0.023 0.028 0.038" />
            </geometry>
        </collision>
    </link>
    <gazebo reference="gripper_finger1_link">
        <material>Gazebo/Gray</material>
        <selfCollide>true</selfCollide>
        <gravity>true</gravity>
    </gazebo>
    <joint name="gripper_finger1_joint" type="prismatic">
        <origin rpy="0 0 0" xyz="0.019 0 0" />
        <axis xyz="0 1 0" />
        <limit effort="30" lower="0.001" upper="0.0158" velocity="0.01" />
        <parent link="gripper_finger_base_link" />
        <child link="gripper_finger1_link" />
    </joint>
    <link name="gripper_finger2_link">
        <inertial>
            <mass value="1e-05" />
            <origin xyz="0 0 0" rpy="0 0 0" />
            <inertia ixx="6.666666666666667e-10" ixy="0" ixz="0" iyy="1.0933333333333333e-09" iyz="0" izz="1.7333333333333333e-09" />
        </inertial>
        <visual>
            <origin rpy="1.5707963267948966 0 1.5707963267948966" xyz="0 0.0115 0" />
            <geometry>
                <mesh filename="package://pincher_arm_description/meshes/pincher_finger.stl" scale=".01 .01 .01" />
            </geometry>
            <material name="Gray" />
        </visual>
        <collision>
            <origin rpy="1.5707963267948966 0 1.5707963267948966" xyz="0 0.0115 0" />
            <geometry>
                <box size="0.023 0.028 0.038" />
            </geometry>
        </collision>
    </link>
    <gazebo reference="gripper_finger2_link">
        <material>Gazebo/Gray</material>
        <selfCollide>true</selfCollide>
        <gravity>true</gravity>
    </gazebo>
    <joint name="gripper_finger2_joint" type="prismatic">
        <origin rpy="3.141592653589793 0 0" xyz="0.019 0 0" />
        <axis xyz="0 1 0" />
        <limit effort="30" lower="0.001" upper="0.0158" velocity="0.01" />
        <parent link="gripper_finger_base_link" />
        <child link="gripper_finger2_link" />
        <!-- <mimic joint="gripper_finger1_joint"/> -->
    </joint>
    <!-- fake gripper joint -->
    <link name="gripper_fake_link" />
    <joint name="gripper_fake_joint" type="revolute">
        <origin rpy="0 0 0" xyz="0.02 0 0" />
        <parent link="gripper_finger_base_link" />
        <child link="gripper_fake_link" />
        <limit effort="30" lower="-3.14" upper="3.14" velocity="1" />
        <axis xyz="1 0 0" />
    </joint>
    <transmission name="trans_arm_shoulder_pan_joint">
        <type>transmission_interface/SimpleTransmission</type>
        <joint name="arm_shoulder_pan_joint">
            <hardwareInterface>hardware_interface/EffortJointInterface</hardwareInterface>
        </joint>
        <actuator name="arm_shoulder_pan_joint_motor">
            <hardwareInterface>hardware_interface/EffortJointInterface</hardwareInterface>
            <mechanicalReduction>1</mechanicalReduction>
        </actuator>
    </transmission>
    <transmission name="trans_arm_shoulder_lift_joint">
        <type>transmission_interface/SimpleTransmission</type>
        <joint name="arm_shoulder_lift_joint">
            <hardwareInterface>hardware_interface/EffortJointInterface</hardwareInterface>
        </joint>
        <actuator name="arm_shoulder_lift_joint_motor">
            <hardwareInterface>hardware_interface/EffortJointInterface</hardwareInterface>
            <mechanicalReduction>1</mechanicalReduction>
        </actuator>
    </transmission>
    <transmission name="trans_arm_elbow_flex_joint">
        <type>transmission_interface/SimpleTransmission</type>
        <joint name="arm_elbow_flex_joint">
            <hardwareInterface>hardware_interface/EffortJointInterface</hardwareInterface>
        </joint>
        <actuator name="arm_elbow_flex_joint_motor">
            <hardwareInterface>hardware_interface/EffortJointInterface</hardwareInterface>
            <mechanicalReduction>1</mechanicalReduction>
        </actuator>
    </transmission>
    <transmission name="trans_arm_wrist_flex_joint">
        <type>transmission_interface/SimpleTransmission</type>
        <joint name="arm_wrist_flex_joint">
            <hardwareInterface>hardware_interface/EffortJointInterface</hardwareInterface>
        </joint>
        <actuator name="arm_wrist_flex_joint_motor">
            <hardwareInterface>hardware_interface/EffortJointInterface</hardwareInterface>
            <mechanicalReduction>1</mechanicalReduction>
        </actuator>
    </transmission>
    <transmission name="trans_gripper_joint">
        <type>transmission_interface/SimpleTransmission</type>
        <joint name="gripper_joint">
            <hardwareInterface>hardware_interface/EffortJointInterface</hardwareInterface>
        </joint>
        <actuator name="gripper_joint_motor">
            <hardwareInterface>hardware_interface/EffortJointInterface</hardwareInterface>
            <mechanicalReduction>1</mechanicalReduction>
        </actuator>
    </transmission>
    <transmission name="trans_gripper_finger1_joint">
        <type>transmission_interface/SimpleTransmission</type>
        <joint name="gripper_finger1_joint">
            <hardwareInterface>hardware_interface/EffortJointInterface</hardwareInterface>
        </joint>
        <actuator name="gripper_finger1_joint_motor">
            <hardwareInterface>hardware_interface/EffortJointInterface</hardwareInterface>
            <mechanicalReduction>1</mechanicalReduction>
        </actuator>
    </transmission>
    <transmission name="trans_gripper_finger2_joint">
        <type>transmission_interface/SimpleTransmission</type>
        <joint name="gripper_finger2_joint">
            <hardwareInterface>hardware_interface/EffortJointInterface</hardwareInterface>
        </joint>
        <actuator name="gripper_finger2_joint_motor">
            <hardwareInterface>hardware_interface/EffortJointInterface</hardwareInterface>
            <mechanicalReduction>1</mechanicalReduction>
        </actuator>
    </transmission>
    <transmission name="trans_gripper_fake_joint">
        <type>transmission_interface/SimpleTransmission</type>
        <joint name="gripper_fake_joint">
            <hardwareInterface>hardware_interface/EffortJointInterface</hardwareInterface>
        </joint>
        <actuator name="gripper_fake_joint_motor">
            <hardwareInterface>hardware_interface/EffortJointInterface</hardwareInterface>
            <mechanicalReduction>1</mechanicalReduction>
        </actuator>
    </transmission>
</robot>

